Workbook
Name A: #REF!
Name A: #REF!
Name A: #REF!
Name A: #REF!
Name aa: [1]External!#REF!
Name aa: [1]External!#REF!
Name aa: [1]External!#REF!
Name aa: #REF!
Name aa: [1]External!#REF!
Name aaa: '[2]Recap Architect'!#REF!
Name aaa: '[2]Recap Architect'!#REF!
Name aaa: '[2]Recap Architect'!#REF!
Name aaa: '[2]Recap Architect'!#REF!
Name aaa: #REF!
Name aaa: '[2]Recap Architect'!#REF!
Name aaa: '[2]Recap Architect'!#REF!
Name Adjustmentarchitectural: [3]Architectural!#REF!
Name Adjustmentarchitectural: [3]Architectural!#REF!
Name Adjustmentarchitectural: [3]Architectural!#REF!
Name Adjustmentarchitectural: #REF!
Name Adjustmentarchitectural: [4]Architectural!#REF!
Name Adjustmentarchitectural: [3]Architectural!#REF!
Name Adjustmentexternal: [3]External!#REF!
Name Adjustmentexternal: [3]External!#REF!
Name Adjustmentexternal: [3]External!#REF!
Name Adjustmentexternal: #REF!
Name Adjustmentexternal: [4]External!#REF!
Name Adjustmentexternal: [3]External!#REF!
Name Adjustmentlift: [3]Lift!#REF!
Name Adjustmentlift: [3]Lift!#REF!
Name Adjustmentlift: [3]Lift!#REF!
Name Adjustmentlift: #REF!
Name Adjustmentlift: [4]Lift!#REF!
Name Adjustmentlift: [3]Lift!#REF!
Name Adjustmentpiles: #REF!
Name Adjustmentpiles: #REF!
Name Adjustmentpiles: #REF!
Name Adjustmentpiles: #REF!
Name Adjustmentpiles: #REF!
Name Adjustmentstructural: '[3] Structural'!#REF!
Name Adjustmentstructural: '[3] Structural'!#REF!
Name Adjustmentstructural: '[3] Structural'!#REF!
Name Adjustmentstructural: #REF!
Name Adjustmentstructural: '[4] Structural'!#REF!
Name Adjustmentstructural: '[3] Structural'!#REF!
Name Adjustmenttravellingcrane: [3]Travel.Cranes!#REF!
Name Adjustmenttravellingcrane: [3]Travel.Cranes!#REF!
Name Adjustmenttravellingcrane: [3]Travel.Cranes!#REF!
Name Adjustmenttravellingcrane: #REF!
Name Adjustmenttravellingcrane: [4]Travel.Cranes!#REF!
Name Adjustmenttravellingcrane: [3]Travel.Cranes!#REF!
Name as: [2]Lift!#REF!
Name as: [2]Lift!#REF!
Name as: [2]Lift!#REF!
Name as: [2]Lift!#REF!
Name as: #REF!
Name as: [2]Lift!#REF!
Name as: [2]Lift!#REF!
Name B: #REF!
Name B: #REF!

Sheet Civil
A2: FITOUT WORKS TO CARREFOUR SAVA AT SPORT SOCIETY, DUBAI, UAE
A3: SECTION 1 - FIT-OUT WORKS
A4: BILL NO. 1 - BUILDERS WORK
D6: AL KENDI | H6: COGENT
A7: ITEM | B7: DESCRIPTION | D7: QUANTITY | E7: UNIT | F7: RATE | G7: AMOUNT | H7: QUANTITY | I7: UNIT | J7: RATE | K7: AMOUNT
A9: s
B10: DEMOLITIONS
B12: Note:
B13: All rates shall include for clearing away debris and rubbish as
B14: the work proceeds and for making good all work disturbed.
B16: The Tenderer is to ensure that he reviews all existing
B17: structural drawings of the existing shopping centre before
B18: demolishing any areas adjacent or inside the existing
B19: shopping centre in order to ensure the safety and integrity
B20: of the existing structure. No claims for failure to do so will be
B21: entertained.
B23: The tenderer shall allow for the preparation of drawings and all
B24: necessary testing of existing installations, to be demolished,
... B34: Sundries
A36: 1 | B36: Allow for removal of existing shopfront, single layer dry wall | D36: 1 | E36: Item | F36: 9000 | G36: =D36*F36 -> 9000 | H36: 1 | I36: Item | J36: 9500 | K36: =H36*J36 -> 9500
A38: =A36+1 -> 2 | B38: Allow for providing protection to existing finished surfaces
B39: in accordance with the instructions issued by the Engineer. | D39: 1 | E39: Item | F39: =696*13 -> 9048 | G39: =D39*F39 -> 9048 | H39: 1 | I39: Item | J39: 12000 | K39: =H39*J39 -> 12000
B74: CARRIED TO SUMMARY | F74: AED | G74: =SUM(G9:G72) -> 18048 | J74: AED | K74: =SUM(K9:K72) -> 21500
B77: CONCRETE SCREED
B79: Concrete screed to receive floor finishes (measured elsewhere)
B80: as per the drawings and the specification. (refer drawing CEC-SP258-AR-700)
A82: 1 | B82: 80mm Thick average ready mix 300 concrete screed 30N/mm2 with 1 layer of
B83: 6mm BRC steel mesh, ref. CS01 (bakery, sales,office, pantry, warehouse,
B84: cold room, freezer room) | D84: 691 | E84: m2 | F84: 85 | G84: =D84*F84 -> 58735 | H84: 691 | I84: m2 | J84: 130 | K84: =H84*J84 -> 89830
A86: =A82+1 -> 2 | B86: 80mm Thick average ready mix 250 concrete screed 25N/mm2, ref. CS02
B87: (toilet) | D87: 5 | E87: m2 | F87: 85 | G87: =D87*F87 -> 425 | H87: 5 | I87: m2 | J87: 130 | K87: =H87*J87 -> 650
B138: CARRIED TO SUMMARY | F138: AED | G138: =SUM(G76:G136) -> 59160 | J138: AED | K138: =SUM(K76:K136) -> 90480
B141: MASONRY
B143: Hollow block work bedded and jointed in mortar including bracing beams,
B144: columns, stiffeners, bed joint reinforcement and head restraint as per the
B145: drawings and the specification (refer drawing CEC-SP258-AR-400)
A147: 1 | B147: 100mm Thick hollow blockwall, upto 3,000mm high ref. W02, (cleaner room, toilet) | D147: 17 | E147: m2 | F147: 180 | G147: =D147*F147 -> 3060 | H147: 17 | I147: m2 | J147: 180 | K147: =H147*J147 -> 3060
A149: =A147+1 -> 2 | B149: 150mm Thick hollow blockwall,upto 3,000mm high ref. W04 | D149: 295 | E149: m2 | F149: 190 | G149: =D149*F149 -> 56050 | H149: 295 | I149: m2 | J149: 190 | K149: =H149*J149 -> 56050
B150: (bakery prep, sales area, entrance area, pantry, warehouse, cleaner room,
B151: toilet, cold room, freezer room)
...

Sheet PL 
A2: =Civil!A2 -> FITOUT WORKS TO CARREFOUR SAVA AT SPORT SOCIETY, DUBAI, UAE
A3: SECTION 1 - FIT-OUT WORKS
A4: BILL NO. 2 - PLUMBING WORKS
D6: AL KENDI | H6: COGENT
A7: ITEM | B7: DESCRIPTION | D7: QUANTITY | E7: UNIT | F7: RATE | G7: AMOUNT | H7: QUANTITY | I7: UNIT | J7: RATE | K7: AMOUNT
B10: PLUMBING INSTALLATIONS
B12: Drainage system
B14: Supply and installation of drainage pipes, including supports,
B15: fittings, fixings, injection to seal the gaps, accessories, chipping, cutting, etc.,
B16: as per the drawings and the specification. (refer drawing CEC-SP255-DR-01/02)
A18: 1 | B18: 50mm Diameter waste pipe | D18: 18 | E18: m | F18: 105 | G18: =D18*F18 -> 1890 | H18: 18 | I18: m | J18: 65 | K18: =H18*J18 -> 1170
A20: =+A18+1 -> 2 | B20: 82mm Diameter waste pipe | D20: 14 | E20: m | F20: 140 | G20: =D20*F20 -> 1960 | H20: 14 | I20: m | J20: 95 | K20: =H20*J20 -> 1330
A22: =A20+1 -> 3 | B22: 110mm Diameter waste pipe | D22: 35 | E22: m | F22: 180 | G22: =D22*F22 -> 6300 | H22: 35 | I22: m | J22: 130 | K22: =H22*J22 -> 4550
B24: Supply and installation of Condensate drain pipes;including supports,
B25: fittings, fixings, injection to seal the gaps, insulation accessories, etc.,
B26: as per the drawings and the specification to connect with the
B27: AC and refrigeration equipment's. (refer drawing CEC-SP255-DR-01/02)
A29: =A22+1 -> 4 | B29: 50 mm Diameter pipe | D29: 53 | E29: m | F29: 150 | G29: =D29*F29 -> 7950 | H29: 53 | I29: m | J29: 65 | K29: =H29*J29 -> 3445
A31: =A29+1 -> 5 | B31: 32 mm Diameter pipe | D31: 19 | E31: m | F31: 115 | G31: =D31*F31 -> 2185 | H31: 19 | I31: m | J31: 50 | K31: =H31*J31 -> 950
B33: Supply and installation of soil drain pipes;including supports,
B34: fittings, fixings, injection to seal the gaps, insulation accessories, etc.,
B35: as per the drawings and the specification to connect with the
B36: AC and refrigeration equipment's. (refer drawing CEC-SP255-DR-01/02)
A38: =A31+1 -> 6 | B38: 100 mm Diameter pipe | D38: 2 | E38: m | F38: 180 | G38: =D38*F38 -> 360 | H38: 2 | I38: m | J38: 250 | K38: =H38*J38 -> 500
B40: Drainage system (cont'd)
B42: Supply and installation of following accessories including Clean Out;
B43: FCO,cutting/chasing through existing concrete floor slab as
B44: necessary, excavation, back filling, fittings and fixings as per
B45: the drawings and the specification. (refer drawing CEC-SP255-DR-01)
A47: =A38+1 -> 7 | B47: Floor trap, Ref. FT | D47: 9 | E47: No | F47: 375 | G47: =D47*F47 -> 3375 | H47: 9 | I47: No | J47: 550 | K47: =H47*J47 -> 4950
A49: =A47+1 -> 8 | B49: Floor clean out,ref.FCO | D49: 5 | E49: No | F49: =+F47 -> 375 | G49: =D49*F49 -> 1875 | H49: 5 | I49: No | J49: 400 | K49: =H49*J49 -> 2000
A51: =A49+1 -> 9 | B51: Clean out, ref. CO | D51: 9 | E51: No | F51: =+F49 -> 375 | G51: =D51*F51 -> 3375 | H51: 9 | I51: No | J51: 280 | K51: =H51*J51 -> 2520
A53: =A51+1 -> 10 | B53: U trap | D53: 5 | E53: No | F53: 250 | G53: =D53*F53 -> 1250 | H53: 5 | I53: No | J53: 320 | K53: =H53*J53 -> 1600
B55: Sundries
A57: =A53+1 -> 11 | B57: Allowance for connecting new drainage system to existing
B58: drainage system as per the drawings and specifications. | D58: 1 | E58: Item | F58: =+(550*2)+650+1500 -> 3250 | G58: =D58*F58 -> 3250 | H58: 1 | I58: Item | J58: 750 | K58: =H58*J58 -> 750
A60: =A57+1 -> 12 | B60: Allow for checking for leakage and rectification in all cold storage areas | D60: 1 | E60: Item | F60: 500 | G60: =D60*F60 -> 500 | H60: 1 | I60: Item | J60: 1100 | K60: =H60*J60 -> 1100
A62: =A60+1 -> 13 | B62: Allow for all necessary coring with slab scanning through existing
B63: concrete slabs, beams, etc., related to all MEP works as per the
B64: drawings and specification | D64: 1 | E64: Item | F64: =6*650 -> 3900 | G64: =D64*F64 -> 3900 | H64: 1 | I64: Item | J64: 1200 | K64: =H64*J64 -> 1200
...

Sheet FF 
A2: =Civil!A2 -> FITOUT WORKS TO CARREFOUR SAVA AT SPORT SOCIETY, DUBAI, UAE
A3: SECTION 1 - FIT-OUT WORKS
A4: BILL NO. 3 - FIRE PROTECTION WORKS
D6: AL KENDI | H6: COGENT
A7: ITEM | B7: DESCRIPTION | D7: QUANTITY | E7: UNIT | F7: RATE | G7: AMOUNT | H7: QUANTITY | I7: UNIT | J7: RATE | K7: AMOUNT
B10: FIRE PROTECTION INSTALLATIONS
B11: (All the fire installations should be as per the current CDA
B12: requirements and all the fire systems should have compatibility
B13: with fire alarm, BMS, Smoke Management systems and also
B14: with all other Building Automation system.)
B16: NOTE:
B17: Tenderers are to note that the onus lies with them to
B18: assess and establish the exact extent of all existing
B19: electro-mechanical systems constructed and to allow for
B20: the removal, alteration, relocation, etc, of unnecessary
B21: and all new installations required to ensure that the new fit-out
B22: conforms to the exact requirements and specifications as intended.
... B32: drawings and specification. (refer drawing CEC-SP258-FF-01/02)
A34: =+A23+1 -> 1 | B34: 25 mm Dia pipe | D34: 41 | E34: m | F34: 115 | G34: =D34*F34 -> 4715 | H34: 41 | I34: m | J34: 50 | K34: =H34*J34 -> 2050
A36: =+A34+1 -> 2 | B36: 32 mm Dia pipe | D36: 20 | E36: m | F36: 135 | G36: =D36*F36 -> 2700 | H36: 20 | I36: m | J36: 75 | K36: =H36*J36 -> 1500
A38: =A36+1 -> 3 | B38: 40 mm Dia pipe | D38: 11 | E38: m | F38: 165 | G38: =D38*F38 -> 1815 | H38: 11 | I38: m | J38: 95 | K38: =H38*J38 -> 1045
A40: =A38+1 -> 4 | B40: 50 mm Dia pipe | D40: 8 | E40: m | F40: 200 | G40: =D40*F40 -> 1600 | H40: 8 | I40: m | J40: 110 | K40: =H40*J40 -> 880
A42: =A40+1 -> 5 | B42: 65 mm Dia pipe | D42: 27 | E42: m | F42: 235 | G42: =D42*F42 -> 6345 | H42: 27 | I42: m | J42: 125 | K42: =H42*J42 -> 3375
B44: Supply and install sprinklers, including all fittings and fixtures,
B45: in accordance with the drawings and the specification
B46: (refer drawing CEC-SP258-FF-01/02)
B47: (New sprinklers must be same rating as existing)
A49: =A42+1 -> 6 | B49: Dry type sprinkler head, 5.6k factor | D49: 2 | E49: No | F49: 700 | G49: =D49*F49 -> 1400 | H49: 2 | I49: No | J49: 650 | K49: =H49*J49 -> 1300
A51: =A49+1 -> 7 | B51: 1/2" pendent sprinkler head, quick response chrome finish - 68° C, 5.6k factor | D51: 12 | E51: No | F51: 90 | G51: =D51*F51 -> 1080 | H51: 12 | I51: No | J51: 115 | K51: =H51*J51 -> 1380
B53: Equipment including all necessary fittings, fixings,
B54: accessories and supports as per the drawings and specification.
B55: (refer drawing CEC-SP258-FF-01/02)
A57: =A51+1 -> 8 | B57: 4kg DCP fire extinguisher | D57: 4 | E57: No | F57: 250 | G57: =D57*F57 -> 1000 | H57: 4 | I57: No | J57: 300 | K57: =H57*J57 -> 1200
A59: =A57+1 -> 9 | B59: 5kg CO2 fire extinguisher | D59: 5 | E59: No | F59: 250 | G59: =D59*F59 -> 1250 | H59: 5 | I59: No | J59: 300 | K59: =H59*J59 -> 1500
A61: =A59+1 -> 10 | B61: Fire blanket | D61: 1 | E61: No | F61: 200 | G61: =D61*F61 -> 200 | H61: 1 | I61: No | J61: 350 | K61: =H61*J61 -> 350
B71: CARRIED TO COLLECTION | F71: AED | G71: =SUM(G10:G69) -> 22105 | J71: AED | K71: =SUM(K10:K69) -> 14580
B74: FIRE PROTECTION INSTALLATIONS (cont'd)
B76: Fire Protection System (cont'd)
B78: Sundries
A80: =A76+1 -> 1 | B80: Allow for minor mofiication of sprinkler lines and sprinklers as per drawings and
...

Sheet HVAC
A2: =[9]Civil!A2 -> FITOUT WORKS TO CARREFOUR SAVA AT SPORT SOCIETY, DUBAI, UAE
A3: SECTION 1 - FIT-OUT WORKS
A4: BILL NO. 4 - MECHANICAL WORKS
D6: AL KENDI | H6: COGENT
A7: ITEM | B7: DESCRIPTION | D7: QUANTITY | E7: UNIT | F7: RATE | G7: AMOUNT | H7: QUANTITY | I7: UNIT | J7: RATE | K7: AMOUNT
B10: MECHANICAL ENGINEERING INSTALLATIONS
B12: NOTE:
B13: Tenderers are to note that the onus lies with them to
B14: assess and establish the exact extent of all existing
B15: electro-mechanical systems constructed and to allow for
B16: the removal, alteration, relocation, etc, of unnecessary
B17: and all new installations required to ensure that the new fit-out
B18: conforms to the exact requirements and specifications as intended.
B20: Note: All mechanical items must be in compliance with MAF
B21: zero sustainabilty policy
B23: Chilled Water System Installations
B25: Chilled water piping, fittings, supports in accordance with the
... B32: (refer drawing CEC-SP258-AC-02)
A34: =1 -> 1 | B34: 25mm diameter | D34: 2 | E34: m | F34: 125 | G34: =D34*F34 -> 250 | H34: 2 | I34: m | J34: 125 | K34: =H34*J34 -> 250
A36: =A34+1 -> 2 | B36: 32mm diameter | D36: 43 | E36: m | F36: 145 | G36: =D36*F36 -> 6235 | H36: 43 | I36: m | J36: 156 | K36: =H36*J36 -> 6708
A38: =A36+1 -> 3 | B38: 40mm diameter | D38: 10 | E38: m | F38: 180 | G38: =D38*F38 -> 1800 | H38: 10 | I38: m | J38: 160 | K38: =H38*J38 -> 1600
A40: =A38+1 -> 4 | B40: 50mm diameter | D40: 12 | E40: m | F40: 225 | G40: =D40*F40 -> 2700 | H40: 12 | I40: m | J40: 180 | K40: =H40*J40 -> 2160
A42: =A40+1 -> 5 | B42: 65mm diameter | D42: 17 | E42: m | F42: 275 | G42: =D42*F42 -> 4675 | H42: 17 | I42: m | J42: 260 | K42: =H42*J42 -> 4420
B44: Air conditioning system as per the drawings and the specification
B46: Supply and Install ductwork and specialties complete with
B47: insulation, protective cladding as required, bellmouth opening, wire mesh,
B48: plenum box, fittings, splitter, fire, volume control and other
B49: dampers, supports for ducts, etc complete in accordance with the
B50: drawings and the specification. (refer drawing CEC-SP255-AC-01)
A52: =A42+1 -> 6 | B52: Supply and return rectangular air ducts | D52: 19 | E52: m2 | F52: 170 | G52: =D52*F52 -> 3230 | H52: 19 | I52: m2 | J52: 280 | K52: =H52*J52 -> 5320
A54: =A52+1 -> 7 | B54: Supply circular air ducts | D54: 144 | E54: m | F54: =170+130 -> 300 | G54: =D54*F54 -> 43200 | H54: 144 | I54: m | J54: 280 | K54: =H54*J54 -> 40320
A56: =A54+1 -> 8 | B56: Allow for flexible duct as per the drawings and specification | D56: 1 | E56: Item | F56: =4*80 -> 320 | G56: =D56*F56 -> 320 | H56: 1 | I56: Item | J56: 2500 | K56: =H56*J56 -> 2500
A58: =A56+1 -> 9 | B58: Allow for rectification of all bended flexible ducts and air leakages as notes
B59: given in the drawing. | D59: 1 | E59: Item | F59: 100 | G59: =D59*F59 -> 100 | H59: 1 | I59: Item | K59: =H59*J59 -> 0
B76: CARRIED TO COLLECTION | F76: AED | G76: =SUM(G10:G74) -> 62510 | J76: AED | K76: =SUM(K10:K74) -> 63278
B78: Air conditioning system (Cont'd)
B81: Air conditioning equipment
B83: Fan Coil units including fans, air filters, all valves, strainers, controls,
B84: thermostats including connections/interfacing to existing controls and
B85: valve package, instruments,cooling coils, thermal and acoustic
...

Sheet Electrical 
A2: =[9]Civil!A2 -> FITOUT WORKS TO CARREFOUR SAVA AT SPORT SOCIETY, DUBAI, UAE
A3: SECTION 1 - FIT-OUT WORKS
A4: BILL NO. 5 - ELECTRICAL WORKS
D6: AL KENDI | H6: COGENT
A7: ITEM | B7: DESCRIPTION | D7: QUANTITY | E7: UNIT | F7: RATE | G7: AMOUNT | H7: QUANTITY | I7: UNIT | J7: RATE | K7: AMOUNT
B10: ELECTRICAL ENGINEERING INSTALLATIONS
B12: NOTE:
B13: Tenderers are to note that the onus lies with them to
B14: assess and establish the exact extent of all existing
B15: electro-mechanical systems constructed and to allow for
B16: the removal, alteration, relocation, etc, of unnecessary
B17: and all new installations required to ensure that the new fit-out
B18: conforms to the exact requirements and specifications as intended.
B20: Tenderers shall verify all existing electrical installations at site
B21: and all required modifications to existing shall be included in
B22: his price without additional cost.
B24: Note: All electrical items must be in compliance with MAF
... B31: specification (refer drawing CEC-SP258-PD-01/02)
A33: =1 -> 1 | B33: DB-LP | D33: 1 | E33: No | F33: 6000 | G33: =D33*F33 -> 6000 | H33: 1 | I33: No | J33: 6200 | K33: =H33*J33 -> 6200
A35: =A33+1 -> 2 | B35: DB-REF | D35: 1 | E35: No | F35: 6500 | G35: =D35*F35 -> 6500 | H35: 1 | I35: No | J35: 6500 | K35: =H35*J35 -> 6500
A37: =A35+1 -> 3 | B37: SMDB-GF-SH1 | D37: 1 | E37: No | F37: 12500 | G37: =D37*F37 -> 12500 | H37: 1 | I37: No | J37: 14500 | K37: =H37*J37 -> 14500
B74: CARRIED TO COLLECTION | F74: AED | G74: =SUM(G11:G70) -> 25000 | J74: AED | K74: =SUM(K11:K70) -> 27200
B76: Cable trays and cable trunking
B78: Supply and install cable trunking as per the drawings and the specification
B79: (refer drawing CEC-SP258-PD-01/02)
A81: 1 | B81: 100 x 50mm GI trunking | D81: 125 | E81: m | F81: 90 | G81: =D81*F81 -> 11250 | H81: 125 | I81: m | J81: 140 | K81: =H81*J81 -> 17500
B83: Supply and install GI cable tray as per the drawings and the specification
B84: (refer drawing CEC-SP258-PD-01/02)
A86: =A81+1 -> 2 | B86: 100 x 50mm GI cable tray HDRF | D86: 39 | E86: m | F86: 85 | G86: =D86*F86 -> 3315 | H86: 39 | I86: m | J86: 140 | K86: =H86*J86 -> 5460
B88: Isolators, etc.
B90: Supply and Installation of cables/wiring including containment
B91: to followings as per the drawings and specification
B92: (Contractor shall include cables, accessories and Containment etc. as
B93: required from Distribution boards to Isolators and Isolators to relevant
B94: equipment in their price for below items. Actual Isolator device
B95: must be price separately under Isolators)
B96: (refer drawing CEC-SP258-PD-01/02)
A98: =A86+1 -> 3 | B98: Cable to 16A , FP Isolator | D98: 1 | E98: No | F98: 550 | G98: =D98*F98 -> 550 | H98: 1 | I98: No | J98: 1300 | K98: =H98*J98 -> 1300
A100: =+A98+1 -> 4 | B100: Cable to 20A , FP Isolator | D100: 1 | E100: No | F100: =55*45 -> 2475 | G100: =D100*F100 -> 2475 | H100: 1 | I100: No | J100: 1050 | K100: =H100*J100 -> 1050
A102: =A100+1 -> 5 | B102: Cable to 40A , FP Isolator | D102: 1 | E102: No | F102: =55*60 -> 3300 | G102: =D102*F102 -> 3300 | H102: 1 | I102: No | J102: 2150 | K102: =H102*J102 -> 2150
...

Sheet Additional Items
A2: =Civil!A2 -> FITOUT WORKS TO CARREFOUR SAVA AT SPORT SOCIETY, DUBAI, UAE
A3: SECTION 1 - FIT-OUT WORKS
A4: BILL NO. 6 - ADDITIONAL ITEMS
D6: AL KENDI | H6: COGENT
A7: ITEM | B7: DESCRIPTION | D7: QUANTITY | E7: UNIT | F7: RATE | G7: AMOUNT | H7: QUANTITY | I7: UNIT | J7: RATE | K7: AMOUNT
B10: Additional Items; Civil works
B12: The Contractor shall list and price below, the items and
B13: quantities of additional or deduction for any Bill of Quantities.
B14: Item(s) and or any missing items that in his opinion are
B15: necessary for the full and satisfactory completion of the work as
B16: described in the specifications or shown on the drawings and
B17: for which either expressed or implied provision is required and
B18: which are not covered by the items or the rates in the bill of
B19: quantities. Any such items not listed below shall be deemed
B20: to be included
A22: 1 | B22: Mobilization/ Demobilization charges | D22: 1 | E22: Item | F22: 11000 | G22: =D22*F22 -> 11000
A24: 2 | B24: CAR policy charges | D24: 1 | E24: Item | F24: 4000 | G24: =D24*F24 -> 4000
A26: 1 | B26: Allow for removal of existing separate partition, single layer dry wall
B28: Supply and install 2 coats of Mapelastic smart cementitious waterproofing
B29: coat with mapetex sel polyproplene fabric as a reinforcement between the 2
B30: coats from mapei as a bottom layer waterproofing as per the drawings and
B31: the specification (refer drawing CEC-SP258-AR-600)
A32: 2 | B32: To floors as bottom layer, ref. WP-01 (salesarea, pantry, toilet)
B34: Cement and sand plaster to existing insitu concrete or block work
B35: as per the drawings and the specification (refer drawing CEC-SP258-AR-704)
A36: 3 | B36: Fair faced cement plaster to receive paint finishes, ref. PL01
A38: 4 | B38: Rough finish Sand cement plaster to receive tile finishes, ref. PL02/PL03/PL04
B40: Approved wall tiles with proper backing, fixed with latecret 254 platinum
B41: adhesive, epoxy grouting, glue, all fixing materials, jointed and pointed as per the
B42: drawings and the specification (refer drawing CEC-SP258-AR-704)
A43: 5 | B43: To existing wall, ref. WF03 (cleaner room)
A45: 6 | B45: To newly plastered wall, ref. WF-04 (pantry, bakery)
B47: Supply and install gypsum partition including framing, fixing, fittings, flush
B48: skim plastered joints, rock wool insulation to receive paint finish (measured
B49: elsewhere) complete as per the drawings and the specification.
B50: (refer drawing CEC-SP258-AR-400)
A52: 7 | B52: Wall partition up to 2750mm high , ref.W01 (warehouse, office, pantry)
B54: Supply and install calcium silicate partition including framing, fixing, fittings, flush
B55: skim plastered joints, rock wool insulation to receive paint finish (measured
B56: elsewhere) complete as per the drawings and the specification.
...

Sheet Prov sum
A2: =Civil!A2 -> FITOUT WORKS TO CARREFOUR SAVA AT SPORT SOCIETY, DUBAI, UAE
A3: =Civil!A3 -> SECTION 1 - FIT-OUT WORKS
A4: BILL NO. 7 -PROVISIONAL SUM
D6: AL KENDI | H6: COGENT
A7: ITEM | B7: DESCRIPTION | D7: QUANTITY | E7: UNIT | F7: RATE | G7: AMOUNT | H7: QUANTITY | I7: UNIT | J7: RATE | K7: AMOUNT
B10: PROVISIONAL SUMS
B11: Note:
B12: Builders work means any work required for or in connection
B13: with the relevant provisional sum under which the item appears
B14: or any other work of a general nature that is required in order
B15: to complete the installation. This work will entail but is not
B16: limited to the following: cutting chases and later making good,
B17: corong or leaving holes and later making good as required,
B18: chasing or building in items laid or placed by others, pipe
B19: sleeves including building or casting in, forming openings as
B20: required, timber or steel sub-frames as required, concrete
B21: plinths, cross-overs, etc.
... B29: Provisional Sum for Additional External Signage
A31: =A27+1 -> 1 | B31: Allow a Provisional Sum for Supply and installation of Additional
B32: External Signage | D32: 1 | E32: Item | G32: 50000 | H32: 1 | I32: Item | K32: 50000
A34: =A31+1 -> 2 | B34: Allow for Builders work | D34: 1 | E34: Item | H34: 1 | I34: Item
A36: =A34+1 -> 3 | B36: Allow for attendance, profit and overheads | E36: % | I36: %
B70: CARRIED TO SUMMARY - SECTION 1 | F70: AED | G70: =SUM(G10:G68) -> 50000 | J70: AED | K70: =SUM(K10:K68) -> 50000

Sheet Sec. 1 SUMMARY
A2: =Civil!A2 -> FITOUT WORKS TO CARREFOUR SAVA AT SPORT SOCIETY, DUBAI, UAE
A3: SECTION 1 - SUMMARY
D6: AL KENDI | H6: COGENT
A7: ITEM | B7: DESCRIPTION | G7: AED | K7: AED
B10: SUMMARY SECTION 1 | D10: PAGE NO. | H10: PAGE NO.
C12: =Civil!A4 -> BILL NO. 1 - BUILDERS WORK | D12: 1/15 | G12: =Civil!G979 -> 754212.8 | H12: 1/15 | K12: =Civil!K979 -> 966414.6
C14: ='PL '!A4 -> BILL NO. 2 - PLUMBING WORKS | D14: 1/19 | G14: ='PL '!G268 -> 75485 | H14: 1/19 | K14: ='PL '!K268 -> 58645
C16: ='FF '!A4 -> BILL NO. 3 - FIRE PROTECTION WORKS | D16: 1/22 | G16: ='FF '!G200 -> 29355 | H16: 1/22 | K16: ='FF '!K200 -> 18580
C18: =HVAC!A4 -> BILL NO. 4 - MECHANICAL WORKS | D18: 1/27 | G18: =HVAC!G342 -> 233330 | H18: 1/27 | K18: =HVAC!K342 -> 303378
C20: ='Electrical '!A4 -> BILL NO. 5 - ELECTRICAL WORKS | D20: 1/40 | G20: ='Electrical '!G877 -> 300009 | H20: 1/40 | K20: ='Electrical '!K877 -> 322690
C22: ='Additional Items'!A4 -> BILL NO. 6 - ADDITIONAL ITEMS | D22: 1/43 | G22: ='Additional Items'!G268 -> 225759.4 | H22: 1/43 | K22: ='Additional Items'!K268 -> 8000
C24: ='Prov sum'!A4 -> BILL NO. 7 -PROVISIONAL SUM | D24: 1/44 | G24: ='Prov sum'!G70 -> 50000 | H24: 1/44 | K24: ='Prov sum'!K70 -> 50000
B67: CARRIED TO GENERAL SUMMARY | F67: AED | G67: =SUM(G11:G64) -> 1668151.2 | J67: AED | K67: =SUM(K11:K64) -> 1727707.6

Sheet General Summary
A2: =Civil!A2 -> FITOUT WORKS TO CARREFOUR SAVA AT SPORT SOCIETY, DUBAI, UAE
A3: GENERAL SUMMARY
F5: AL KENDI | G5: COGENT
A6: ITEM | B6: DESCRIPTION | F6: TOTAL AED | G6: TOTAL AED
B9: GENERAL SUMMARY
C11: Section 1 - Fit Out Works
C12: Amount of Page 1/45 | F12: ='Sec. 1 SUMMARY'!G67 -> 1668151.2 | G12: ='Sec. 1 SUMMARY'!K67 -> 1727707.6
F15: =F12 -> 1668151.2 | G15: =G12 -> 1727707.6
C16: Sub-total
C20: Contingency (this contingency is for the sole use of the | F20: 100000 | G20: 100000
C21: Client and may be omitted in part or in its entirety)
B70: TOTAL TO FORM OF TENDER | D70: AED | F70: =SUM(F15:F20) -> 1768151.2 | G70: =G15+G20 -> 1827707.6
