Workbook
Name A: #REF!
Name A: #REF!
Name A: #REF!
Name A: #REF!
Name aa: [1]External!#REF!
Name aa: [1]External!#REF!
Name aa: [1]External!#REF!
Name aa: #REF!
Name aa: [1]External!#REF!
Name aaa: '[2]Recap Architect'!#REF!
Name aaa: '[3]Recap Architect'!#REF!
Name aaa: '[3]Recap Architect'!#REF!
Name aaa: '[3]Recap Architect'!#REF!
Name aaa: #REF!
Name aaa: '[3]Recap Architect'!#REF!
Name aaa: '[3]Recap Architect'!#REF!
Name Adjustmentarchitectural: [4]Architectural!#REF!
Name Adjustmentarchitectural: [4]Architectural!#REF!
Name Adjustmentarchitectural: [4]Architectural!#REF!
Name Adjustmentarchitectural: #REF!
Name Adjustmentarchitectural: [5]Architectural!#REF!
Name Adjustmentarchitectural: [4]Architectural!#REF!
Name Adjustmentexternal: [4]External!#REF!
Name Adjustmentexternal: [4]External!#REF!
Name Adjustmentexternal: [4]External!#REF!
Name Adjustmentexternal: #REF!
Name Adjustmentexternal: [5]External!#REF!
Name Adjustmentexternal: [4]External!#REF!
Name Adjustmentlift: [4]Lift!#REF!
Name Adjustmentlift: [4]Lift!#REF!
Name Adjustmentlift: [4]Lift!#REF!
Name Adjustmentlift: #REF!
Name Adjustmentlift: [5]Lift!#REF!
Name Adjustmentlift: [4]Lift!#REF!
Name Adjustmentpiles: #REF!
Name Adjustmentpiles: #REF!
Name Adjustmentpiles: #REF!
Name Adjustmentpiles: #REF!
Name Adjustmentpiles: #REF!
Name Adjustmentstructural: '[4] Structural'!#REF!
Name Adjustmentstructural: '[4] Structural'!#REF!
Name Adjustmentstructural: '[4] Structural'!#REF!
Name Adjustmentstructural: #REF!
Name Adjustmentstructural: '[5] Structural'!#REF!
Name Adjustmentstructural: '[4] Structural'!#REF!
Name Adjustmenttravellingcrane: [4]Travel.Cranes!#REF!
Name Adjustmenttravellingcrane: [4]Travel.Cranes!#REF!
Name Adjustmenttravellingcrane: [4]Travel.Cranes!#REF!
Name Adjustmenttravellingcrane: #REF!
Name Adjustmenttravellingcrane: [5]Travel.Cranes!#REF!
Name Adjustmenttravellingcrane: [4]Travel.Cranes!#REF!
Name as: [2]Lift!#REF!
Name as: [3]Lift!#REF!
Name as: [3]Lift!#REF!
Name as: [3]Lift!#REF!
Name as: #REF!
Name as: [3]Lift!#REF!
Name as: [3]Lift!#REF!
Name B: #REF!
Name B: #REF!

Sheet Civil
A2: REMODELLING WORKS TO CARREFOUR FIRST AVENUE, DUBAI, UAE
A3: SECTION 1 - FIT-OUT WORKS
A4: BILL NO. 1 - BUILDERS WORK
A7: ITEM | B7: DESCRIPTION | D7: QUANTITY | E7: UNIT | F7: RATE | G7: AMOUNT
B10: DEMOLITIONS
B12: Note:
B13: All rates shall include for clearing away debris and rubbish as
B14: the work proceeds and for making good all work disturbed.
B16: The Tenderer is to ensure that he reviews all existing
B17: structural drawings of the existing shopping centre before
B18: demolishing any areas adjacent or inside the existing
B19: shopping centre in order to ensure the safety and integrity
B20: of the existing structure. No claims for failure to do so will be
B21: entertained.
B23: The tenderer shall allow for the preparation of drawings and all
B24: necessary testing of existing installations, to be demolished,
... B37: specification (refer drawing CEC‑SP249‑AR‑002)
A39: =A22+1 -> 1 | B39: Remove existing blockwall, ref. W02 | D39: 59 | E39: m2 | F39: 100 | G39: =F39*D39 -> 5900
A41: =A39+1 -> 2 | B41: Remove existing blockwall , ref. DW03 | D41: 27 | E41: m2 | F41: 100 | G41: =F41*D41 -> 2700
B43: Remove sandwich panel walls and ceiling including finishes skirting etc. without
B44: causing any damage to existing structure, mep services and carting away and
B45: disposing of all debris at designated areas as per the drawings and the
B46: specification (refer drawing CEC‑SP249‑AR‑002)
A48: =+A41+1 -> 3 | B48: Remove existing sandwich panel wall, ref. W01 | D48: 145 | E48: m2 | F48: 75 | G48: =F48*D48 -> 10875
B50: Take up and remove existing floor finishes, making good and preparing floor for
B51: new floor finish (measured elsewhere), carting away and disposing of all the
B52: debris at designated areas as per the drawings and the specification (refer
B53: drawing CEC‑SP249‑AR‑002)
A55: =A48+1 -> 4 | B55: Remove existing floor tiles, ref. FT-01 | D55: 38 | E55: m2 | F55: 25 | G55: =F55*D55 -> 950
A57: =A55+1 -> 5 | B57: Remove existing floor tiles , ref. FT-02 | D57: 72 | E57: m2 | F57: 25 | G57: =F57*D57 -> 1800
B59: Take up and remove existing ceiling including suspension systems,
B60: making good and preparing for new ceiling finish (measured elsewhere),
B61: carting away and disposing of all the debris at designated areas
B62: as per the drawings and the specification
B63: (refer drawing CEC‑SP249‑AR‑002)
A65: =A57+1 -> 6 | B65: Remove existing ceiling finishes, ref.C-01 | D65: 25 | E65: m2 | F65: 45 | G65: =F65*D65 -> 1125
B71: CARRIED TO COLLECTION | F71: AED | G71: =SUM(G37:G69) -> 23350
B74: DEMOLITIONS (cont'd)
B76: Carefully take out existing doors, hardware and replace with block work
B77: (measured elsewhere) and keep safe to reuse, cap and de-energise all wiring to
...

Sheet PL 
A2: =Civil!A2 -> REMODELLING WORKS TO CARREFOUR FIRST AVENUE, DUBAI, UAE
A3: SECTION 1 - FIT-OUT WORKS
A4: BILL NO. 2 - PLUMBING WORKS
A7: ITEM | B7: DESCRIPTION | D7: QUANTITY | E7: UNIT | F7: RATE | G7: AMOUNT
B10: PLUMBING INSTALLATIONS
B12: DEMOLITIONS
B14: NOTE:
B15: Tenderers are to note that the onus lies with them to
B16: assess and establish the exact extent of all existing
B17: electro-mechanical systems constructed and to allow for
B18: the removal, alteration, relocation, etc, of unnecessary
B19: and all new installations required to ensure that the new fit-out
B20: conforms to the exact requirements and specifications as intended.
B22: Note: All mechanical items must be in compliance with MAF
B23: zero sustainabilty policy
A25: 1 | B25: Allow for cut and removal of drainage system pipeworks, accessories,
B26: equipment, Sanitary fixtures, etc., as shown on drawings/as per
B27: modification requirements and carting away and disposing all debris to
B28: designated areas | D28: 1 | E28: Item | F28: L/S | G28: 3000
A30: =A25+1 -> 2 | B30: Allow for cut and removal of water supply system pipeworks, accessories,
B31: equipment, Sanitary fixtures etc., as shown on drawings/as per
B32: modification requirements and carting away and disposing all debris to
B33: designated areas | D33: 1 | E33: Item | F33: L/S | G33: 2500
B35: Drainage system
B37: Supply and installation of drainage pipes, including supports,
B38: fittings, fixings, injection to seal the gaps, accessories, etc.,
B39: as per the drawings and the specification. (refer drawing CEC-SP249-DR-01)
A41: =+A30+1 -> 3 | B41: 50mm Diameter waste pipe | D41: 6 | E41: m | F41: 250 | G41: =F41*D41 -> 1500
A43: =+A41+1 -> 4 | B43: 82mm Diameter waste pipe | D43: 6 | E43: m | F43: 280 | G43: =F43*D43 -> 1680
B45: Supply and installation of Condensate drain pipes;including supports,
B46: fittings, fixings, injection to seal the gaps, insulation accessories, etc.,
B47: as per the drawings and the specification to connect with the
B48: AC and refrigeration equipment's. (refer drawing CEC-SP249-DR-01)
A50: =A43+1 -> 5 | B50: 25 mm Diameter | D50: 13 | E50: m | F50: 220 | G50: =F50*D50 -> 2860
A52: =A50+1 -> 6 | B52: 50 mm Diameter | D52: 25 | E52: m | F52: 250 | G52: =F52*D52 -> 6250
A54: =A52+1 -> 7 | B54: 82 mm Diameter | D54: 46 | E54: m | F54: 280 | G54: =F54*D54 -> 12880
B72: CARRIED TO COLLECTION | F72: AED | G72: =SUM(G26:G55) -> 30670
B75: Drainage system (cont'd)
B77: Supply and installation of following accessories including Clean Out;
B78: FCO,cutting/chasing through existing concrete floor slab as
...

Sheet FF 
A2: =Civil!A2 -> REMODELLING WORKS TO CARREFOUR FIRST AVENUE, DUBAI, UAE
A3: SECTION 1 - FIT-OUT WORKS
A4: BILL NO. 3 - FIRE PROTECTION WORKS
A7: ITEM | B7: DESCRIPTION | D7: QUANTITY | E7: UNIT | F7: RATE | G7: AMOUNT
B10: FIRE PROTECTION INSTALLATIONS
B11: (All the fire installations should be as per the current CDA
B12: requirements and all the fire systems should have compatibility
B13: with fire alarm, BMS, Smoke Management systems and also
B14: with all other Building Automation system.)
B16: NOTE:
B17: Tenderers are to note that the onus lies with them to
B18: assess and establish the exact extent of all existing
B19: electro-mechanical systems constructed and to allow for
B20: the removal, alteration, relocation, etc, of unnecessary
B21: and all new installations required to ensure that the new fit-out
B22: conforms to the exact requirements and specifications as intended.
... B25: zero sustainabilty policy
A27: =A17+1 -> 1 | B27: Allow for cut and removal of existing fire protection system
B28: pipeworks, accessories, equipments as shown on drawings/as
B29: per modification requirements. | D29: 1 | E29: Item | F29: 1500 | G29: =F29*D29 -> 1500
B31: Fire protection system
B33: Sprinkler system galvanised steel pipe ERW schedule 40 Grade-B to
B34: ASTM A53 standard schedule 40 pipes and fittings including all
B35: necessary valves, fixings, painting, accessories and supports as per
B36: drawings and specification. (refer drawing CEC-SP249-FF-01)
A38: =+A27+1 -> 2 | B38: 25 mm Dia pipe | D38: 6 | E38: m | F38: 250 | G38: =F38*D38 -> 1500
A40: =+A38+1 -> 3 | B40: 32 mm Dia pipe | D40: 1 | E40: m | F40: L/S | G40: 1000
A42: =A40+1 -> 4 | B42: 65 mm Dia pipe | D42: 6 | E42: m | F42: 320 | G42: =F42*D42 -> 1920
B44: Supply and install sprinklers, including all fittings and fixtures,
B45: in accordance with the drawings and the specification
B46: (refer drawing CEC-SP249-FF-01)
B47: (New sprinklers must be same rating as existing)
A49: =A42+1 -> 5 | B49: Quick respond 1/2" pendent sprinkler head. 68'C | D49: 3 | E49: No | F49: 550 | G49: =F49*D49 -> 1650
B51: Sundries
A53: =A49+1 -> 6 | B53: Allow for connecting new fire protection system with existing fire
B54: protection system as per the drawings and specifications. | D54: 1 | E54: Item | F54: 2500 | G54: =F54*D54 -> 2500
B71: CARRIED TO COLLECTION | F71: AED | G71: =SUM(G28:G56) -> 10070
B74: FIRE PROTECTION INSTALLATIONS (cont'd)
B76: Fire Protection Services
B78: Equipment including all necessary fittings, fixings,
...

Sheet HVAC
A2: =Civil!A2 -> REMODELLING WORKS TO CARREFOUR FIRST AVENUE, DUBAI, UAE
A3: SECTION 1 - FIT-OUT WORKS
A4: BILL NO. 4 - MECHANICAL WORKS
A7: ITEM | B7: DESCRIPTION | D7: QUANTITY | E7: UNIT | F7: RATE | G7: AMOUNT
B10: MECHANICAL ENGINEERING INSTALLATIONS
B12: NOTE:
B13: Tenderers are to note that the onus lies with them to
B14: assess and establish the exact extent of all existing
B15: electro-mechanical systems constructed and to allow for
B16: the removal, alteration, relocation, etc, of unnecessary
B17: and all new installations required to ensure that the new fit-out
B18: conforms to the exact requirements and specifications as intended.
B20: Note: All mechanical items must be in compliance with MAF
B21: zero sustainabilty policy
A23: =A13+1 -> 1 | B23: Allow for cut and removal of existing HVAC system pipeworks,
B24: duct works, accessories, equipment as shown on drawings/as
B25: per modification requirements. | D25: 1 | E25: Item | F25: 5500 | G25: 5500
B27: Chilled Water System Installations
B29: Chilled water piping, fittings, supports in accordance with the
B30: drawings and specification. Pipes to specification;ERW mild
B31: steel to ASTM or A53; SCH 40 Grade B including all fittings,
B32: valves, drain cocks, strainers, gauges, insulation, etc. per the
B33: drawings; Pipes in diameter; (Note-Valve set for FAHU/FCUs,etc.
B34: have been included with relevant equipment description and
B35: other valves to included with the rates of pipes).
B36: (refer drawing CEC-SP249-AC-01)
A38: =+A60+1 -> 1 | B38: 25mm diameter | D38: 26 | E38: m | F38: 120 | G38: =F38*D38 -> 3120
A40: =A38+1 -> 2 | B40: 32mm diameter | D40: 29 | E40: m | F40: 150 | G40: =F40*D40 -> 4350
A42: =A40+1 -> 3 | B42: Allow for valve package along chilled water pipes including all fittings,
B43: fixing, etc., complete as required | D43: 1 | E43: Item | F43: 9500 | G43: 9500
B45: Sundries
A47: =A42+1 -> 4 | B47: Allow for connecting new chilled water pipes to the existing chilled
B48: water pipes as per the drawing. | D48: 1 | E48: Item | F48: 25000 | G48: =F48*D48 -> 25000
A50: =A47+1 -> 5 | B50: Allow for chemical flushing of chilled water pipes, chilled water
B51: balancing and third party certification. | D51: 1 | E51: Item | F51: 15000 | G51: =F51*D51 -> 15000
A53: =A50+1 -> 6 | B53: Allow for checking chilled water pipes for leakages, rectify leakages and
B54: add new insulation on all chilled water pipes as notes given in the drawing. | D54: 1 | E54: Item | F54: 17500 | G54: =F54*D54 -> 17500
B72: CARRIED TO COLLECTION | F72: AED | G72: =SUM(G23:G56) -> 79970
B75: Air conditioning system as per the drawings and the specification
B77: Supply and Install ductwork and specialties complete with
...

Sheet Electrical 
A2: =Civil!A2 -> REMODELLING WORKS TO CARREFOUR FIRST AVENUE, DUBAI, UAE
A3: SECTION 1 - FIT-OUT WORKS
A4: BILL NO. 5 - ELECTRICAL WORKS
A7: ITEM | B7: DESCRIPTION | D7: QUANTITY | E7: UNIT | F7: RATE | G7: AMOUNT
B10: ELECTRICAL ENGINEERING INSTALLATIONS
B12: NOTE:
B13: Tenderers are to note that the onus lies with them to
B14: assess and establish the exact extent of all existing
B15: electro-mechanical systems constructed and to allow for
B16: the removal, alteration, relocation, etc, of unnecessary
B17: and all new installations required to ensure that the new fit-out
B18: conforms to the exact requirements and specifications as intended.
B20: Tenderers shall verify all existing electrical installations at site
B21: and all required modifications to existing shall be included in
B22: his price without additional cost.
B24: Note: All electrical items must be in compliance with MAF
... B27: Demolition
A29: 1 | B29: Allow for any removal, alteration, re-location, etc. of existing power
B30: system and make good as per the drawings and specification | D30: 1 | E30: Item | F30: L/S | G30: 2000
B32: Distribution panels
B34: Replace/Modify existing DB's and SMBD's including cables, containments
B35: accessories, fittings, all related works to complete work as per the drawings
B36: and the specification (refer drawing CEC‑SP249‑PD‑02) Note: The contractor
B37: shall allow for the provision of a new DB if modification of the existing
B38: DB is deemed not feasible based on site assessment.
A40: =A29+1 -> 2 | B40: Modify existing SMDB-CF 385 KW | D40: 1 | E40: No | F40: 8500 | G40: =F40*D40 -> 8500
A42: =A40+1 -> 3 | B42: Modify existing DB-L .35.72KW | D42: 1 | E42: No | F42: 3000 | G42: =F42*D42 -> 3000
A44: =+A42+1 -> 4 | B44: Modify existing DB-P1 38.81KW | D44: 1 | E44: No | F44: 3000 | G44: =F44*D44 -> 3000
A46: =+A44+1 -> 5 | B46: Modify existing DB-P2 8KW | D46: 1 | E46: No | F46: 3000 | G46: =F46*D46 -> 3000
A48: =+A46+1 -> 6 | B48: Modify existing DB-AC.34KW | D48: 1 | E48: No | F48: 3000 | G48: =F48*D48 -> 3000
A50: =+A48+1 -> 7 | B50: Modify existing DB-UPS.16.40KW | D50: 1 | E50: No | F50: 3000 | G50: =F50*D50 -> 3000
A52: =A50+1 -> 8 | B52: DB-REF (NEW) | D52: 1 | E52: No | F52: 6000 | G52: =F52*D52 -> 6000
B71: CARRIED TO COLLECTION | F71: AED | G71: =SUM(G29:G53) -> 31500
B74: Isolators, etc.
B76: Supply and Installation of cables/wiring including containment
B77: to followings as per the drawings and specification
B78: (Contractor shall include cables, accessories and Containment etc. as
B79: required from Distribution boards to Isolators and Isolators to relevant
B80: equipment in their price for below items. Actual Isolator device
B81: must be price separately under Isolators)
...

Sheet Additional Items
A2: =Civil!A2 -> REMODELLING WORKS TO CARREFOUR FIRST AVENUE, DUBAI, UAE
A3: SECTION 1 - FIT-OUT WORKS
A4: BILL NO. 6 - ADDITIONAL ITEMS
F6: RATE
A7: ITEM | B7: DESCRIPTION | D7: QUANTITY | E7: UNIT | G7: AMOUNT
B10: Additional Items; Civil works
B12: The Contractor shall list and price below, the items and
B13: quantities of additional or deduction for any Bill of Quantities.
B14: Item(s) and or any missing items that in his opinion are
B15: necessary for the full and satisfactory completion of the work as
B16: described in the specifications or shown on the drawings and
B17: for which either expressed or implied provision is required and
B18: which are not covered by the items or the rates in the bill of
B19: quantities. Any such items not listed below shall be deemed
B20: to be included
A23: A | C23: Hording and sticker (Sliding door works & Mall entrance) | D23: 1 | E23: Item | F23: L/S | G23: 12500
A25: B | C25: Floor Protection | D25: 1 | E25: Item | F25: L/S | G25: 20000
A27: C | C27: Scaffolding and manlift | D27: 1 | E27: Item | F27: L/S | G27: 25000
A29: D | C29: Removal of existing raised floor system(FT-01) | D29: 38 | E29: m2 | F29: L/S | G29: 3000
A31: E | C31: Removal of false ceiling (Fishery, Butchery, Pastry) | D31: 45 | E31: m2 | F31: 45 | G31: =F31*D31 -> 2025
A33: F | C33: SS protection swing type barrier, with height of 90cm | D33: 1 | E33: Item | F33: L/S | G33: 3000
A35: G | C35: Wooden barrier swing both sides, up to associate partition height | D35: 1 | E35: Item | F35: L/S | G35: 1500
B71: CARRIED TO COLLECTION | F71: AED | G71: =SUM(G21:G38) -> 67025
B74: Additional Items; MEP works
B76: The Contractor shall list and price below, the items and
B77: quantities of additional or deduction for any Bill of Quantities.
B78: Item(s) and or any missing items that in his opinion are
B79: necessary for the full and satisfactory completion of the work as
B80: described in the specifications or shown on the drawings and
B81: for which either expressed or implied provision is required and
B82: which are not covered by the items or the rates in the bill of
B83: quantities. Any such items not listed below shall be deemed
B84: to be included
B136: CARRIED TO COLLECTION | F136: AED | G136: =SUM(G84:G107) -> 0
B139: COLLECTION
B141: Additional Items
C143: Additional Items; Civil works- Amount of page 1/43 | G143: =G71 -> 67025
C145: Additional Items; MEP works- Amount of page 1/44 | G145: =G136 -> 0
B201: CARRIED TO SUMMARY - SECTION 1 | F201: AED | G201: =SUM(G142:G148) -> 67025

Sheet Prov sum
A2: =Civil!A2 -> REMODELLING WORKS TO CARREFOUR FIRST AVENUE, DUBAI, UAE
A3: =Civil!A3 -> SECTION 1 - FIT-OUT WORKS
A4: BILL NO. 7 -PROVISIONAL SUM
F6: RATE
A7: ITEM | B7: DESCRIPTION | D7: QUANTITY | E7: UNIT | G7: AMOUNT
B10: PROVISIONAL SUMS
B11: Note:
B12: Builders work means any work required for or in connection
B13: with the relevant provisional sum under which the item appears
B14: or any other work of a general nature that is required in order
B15: to complete the installation. This work will entail but is not
B16: limited to the following: cutting chases and later making good,
B17: corong or leaving holes and later making good as required,
B18: chasing or building in items laid or placed by others, pipe
B19: sleeves including building or casting in, forming openings as
B20: required, timber or steel sub-frames as required, concrete
B21: plinths, cross-overs, etc.
... B29: Provisional Sum for Additional External Signage
A31: =A27+1 -> 1 | B31: Allow a Provisional Sum for Supply and installation of Additional
B32: External Signage | E32: Item | G32: 50000
A34: =A31+1 -> 2 | B34: Allow for Builders work | E34: Item | F34: 5000 | G34: 5000
A36: =A34+1 -> 3 | B36: Allow for attendance, profit and overheads | E36: % | F36: 11000 | G36: 11000
B70: CARRIED TO SUMMARY - SECTION 1 | F70: AED | G70: =SUM(G10:G68) -> 66000

Sheet Sec1SUMMARY
A2: =Civil!A2 -> REMODELLING WORKS TO CARREFOUR FIRST AVENUE, DUBAI, UAE
A3: SECTION 1 - SUMMARY
A7: ITEM | B7: DESCRIPTION | D7: unit | G7: AED
B10: SUMMARY SECTION 1 | D10: PAGE NO.
C12: =Civil!A4 -> BILL NO. 1 - BUILDERS WORK | D12: 1/16 | G12: =Civil!G1031 -> 436085
C14: ='PL '!A4 -> BILL NO. 2 - PLUMBING WORKS | D14: 1/21 | G14: ='PL '!G329 -> 79420
C16: ='FF '!A4 -> BILL NO. 3 - FIRE PROTECTION WORKS | D16: 1/24 | G16: ='FF '!G200 -> 35470
C18: =HVAC!A4 -> BILL NO. 4 - MECHANICAL WORKS | D18: 1/31 | G18: =HVAC!G397 -> 186130
C20: ='Electrical '!A4 -> BILL NO. 5 - ELECTRICAL WORKS | D20: 1/42 | G20: ='Electrical '!G776 -> 229180
C22: ='Additional Items'!A4 -> BILL NO. 6 - ADDITIONAL ITEMS | D22: 1/45 | G22: ='Additional Items'!G201 -> 67025
C24: ='Prov sum'!A4 -> BILL NO. 7 -PROVISIONAL SUM | D24: 1/46 | G24: ='Prov sum'!G70 -> 66000
B67: CARRIED TO GENERAL SUMMARY | F67: AED | G67: =SUM(G12:G26) -> 1099310

Sheet General Summary 
A2: TRN : 100330565100003
A3: BILL OF QUANTITIES
A4: Project : | B4: Fit-out remodeling works at First Avenue, Dubai, UAE | E4: Date : 08.07.2025
A5: Location : | B5: Dubai, UAE | E5: Ref : CCID/T-6050-R0/2025
A6: ITEM | B6: DESCRIPTION | C6: Qty | D6: Unit | E6: Unit Rate (AED) | F6: Total Amount (AED)
B7: GENERAL SUMMARY
A8: 1 | B8: Section 1 - Fit Out Works | C8: 1 | D8: Item | E8: L/S | F8: =Sec1SUMMARY!G67 -> 1099310
A9: 2 | B9: Contingency (this contingency is for the sole use of the Client and may be omitted in part or in its entirely) | C9: 1 | D9: Item | E9: L/S | F9: 100000
B10: TOTAL TO FORM OF TENDER | E10: AED | F10: =SUM(F8:F9) -> 1199310
B12: Exclusion:
A13: 1 | B13: Supply and installation of IT, CCTV,Access Control
A14: 2 | B14: Fit Out Deposit, Drawing Review Fees For the Building
A15: 3 | B15: BMS integration / BTU meter
A16: 4 | B16: Power Upgradation
A17: 5 | B17: Temporary power, water, Toilet Facilities for the labours
B18: Payment Terms:
A19: 1 | B19: 20% advance payment against bank guarantee,70% Progressive as per QS certification of work done, 5% release of retention on re-opening of the store to public and against issuance of taking over certificate, 5% release of retention at the end of the defect liability period and against issuance of defect liability certificate.
B20: Project Duration:
A21: 1 | B21: Within 60 days, starting 7 days after the Engineer’s notice to commence (inclusive of duration for obtaining of all required approvals &/or certificates from the various authorities) Note : 67 Days from the date of LPO, work permit or advance payment which ever is later
B22: Notes:
A23: 1 | B23: All government taxes will be applicable as per authority regulations. (VAT-5% will be charged for all items)
A24: 2 | B24: Any additional requirements from the mall /building/DDA/DCD/DEWA management will be a variation
A25: 3 | B25: Any provisional sum item will have 15% O/H and 7% Profit on supplier / sub-contractor price
A26: 4 | B26: This quotation is valid for 120 days only
A27: 5 | B27: Floor tile replacement 50 Sqm considered based on the site instruction during the site visit.
